Traceback (most recent call last):
  File "/Users/tyler/Environments/nlp/lib/python3.9/site-packages/jupyter_cache/executors/utils.py", line 51, in single_nb_execution
    executenb(
  File "/Users/tyler/Environments/nlp/lib/python3.9/site-packages/nbclient/client.py", line 1204, in execute
    return NotebookClient(nb=nb, resources=resources, km=km, **kwargs).execute()
  File "/Users/tyler/Environments/nlp/lib/python3.9/site-packages/nbclient/util.py", line 84, in wrapped
    return just_run(coro(*args, **kwargs))
  File "/Users/tyler/Environments/nlp/lib/python3.9/site-packages/nbclient/util.py", line 62, in just_run
    return loop.run_until_complete(coro)
  File "/usr/local/Cellar/python@3.9/3.9.12_1/Frameworks/Python.framework/Versions/3.9/lib/python3.9/asyncio/base_events.py", line 647, in run_until_complete
    return future.result()
  File "/Users/tyler/Environments/nlp/lib/python3.9/site-packages/nbclient/client.py", line 663, in async_execute
    await self.async_execute_cell(
  File "/Users/tyler/Environments/nlp/lib/python3.9/site-packages/nbclient/client.py", line 965, in async_execute_cell
    await self._check_raise_for_error(cell, cell_index, exec_reply)
  File "/Users/tyler/Environments/nlp/lib/python3.9/site-packages/nbclient/client.py", line 862, in _check_raise_for_error
    raise CellExecutionError.from_cell_and_msg(cell, exec_reply_content)
nbclient.exceptions.CellExecutionError: An error occurred while executing the following cell:
------------------
lemmatizer = WordNetLemmatizer()

def convert_tag(tag):
    if tag.startswith('J'):
        tag = wordnet.ADJ
    elif tag.startswith('V'):
        tag = wordnet.VERB
    elif tag.startswith('N'):
        tag = wordnet.NOUN
    elif tag.startswith('R'):
        tag = wordnet.ADV
    else:
        tag = ''
    return tag

tagged = tagged.assign(NEW_TAG = tagged['TAG'].apply(convert_tag))
tagged
------------------

[0;31m---------------------------------------------------------------------------[0m
[0;31mLookupError[0m                               Traceback (most recent call last)
File [0;32m~/Environments/nlp/lib/python3.9/site-packages/nltk/corpus/util.py:84[0m, in [0;36mLazyCorpusLoader.__load[0;34m(self)[0m
[1;32m     83[0m [38;5;28;01mtry[39;00m:
[0;32m---> 84[0m     root [38;5;241m=[39m [43mnltk[49m[38;5;241;43m.[39;49m[43mdata[49m[38;5;241;43m.[39;49m[43mfind[49m[43m([49m[38;5;124;43mf[39;49m[38;5;124;43m"[39;49m[38;5;132;43;01m{[39;49;00m[38;5;28;43mself[39;49m[38;5;241;43m.[39;49m[43msubdir[49m[38;5;132;43;01m}[39;49;00m[38;5;124;43m/[39;49m[38;5;132;43;01m{[39;49;00m[43mzip_name[49m[38;5;132;43;01m}[39;49;00m[38;5;124;43m"[39;49m[43m)[49m
[1;32m     85[0m [38;5;28;01mexcept[39;00m [38;5;167;01mLookupError[39;00m:

File [0;32m~/Environments/nlp/lib/python3.9/site-packages/nltk/data.py:583[0m, in [0;36mfind[0;34m(resource_name, paths)[0m
[1;32m    582[0m resource_not_found [38;5;241m=[39m [38;5;124mf[39m[38;5;124m"[39m[38;5;130;01m\n[39;00m[38;5;132;01m{[39;00msep[38;5;132;01m}[39;00m[38;5;130;01m\n[39;00m[38;5;132;01m{[39;00mmsg[38;5;132;01m}[39;00m[38;5;130;01m\n[39;00m[38;5;132;01m{[39;00msep[38;5;132;01m}[39;00m[38;5;130;01m\n[39;00m[38;5;124m"[39m
[0;32m--> 583[0m [38;5;28;01mraise[39;00m [38;5;167;01mLookupError[39;00m(resource_not_found)

[0;31mLookupError[0m: 
**********************************************************************
  Resource [93momw-1.4[0m not found.
  Please use the NLTK Downloader to obtain the resource:

  [31m>>> import nltk
  >>> nltk.download('omw-1.4')
  [0m
  For more information see: https://www.nltk.org/data.html

  Attempted to load [93mcorpora/omw-1.4.zip/omw-1.4/[0m

  Searched in:
    - '/Users/tyler/nltk_data'
    - '/Users/tyler/Environments/nlp/nltk_data'
    - '/Users/tyler/Environments/nlp/share/nltk_data'
    - '/Users/tyler/Environments/nlp/lib/nltk_data'
    - '/usr/share/nltk_data'
    - '/usr/local/share/nltk_data'
    - '/usr/lib/nltk_data'
    - '/usr/local/lib/nltk_data'
**********************************************************************


During handling of the above exception, another exception occurred:

[0;31mLookupError[0m                               Traceback (most recent call last)
Input [0;32mIn [39][0m, in [0;36m<cell line: 16>[0;34m()[0m
[1;32m     13[0m         tag [38;5;241m=[39m [38;5;124m'[39m[38;5;124m'[39m
[1;32m     14[0m     [38;5;28;01mreturn[39;00m tag
[0;32m---> 16[0m tagged [38;5;241m=[39m tagged[38;5;241m.[39massign(NEW_TAG [38;5;241m=[39m [43mtagged[49m[43m[[49m[38;5;124;43m'[39;49m[38;5;124;43mTAG[39;49m[38;5;124;43m'[39;49m[43m][49m[38;5;241;43m.[39;49m[43mapply[49m[43m([49m[43mconvert_tag[49m[43m)[49m)
[1;32m     17[0m tagged

File [0;32m~/Environments/nlp/lib/python3.9/site-packages/pandas/core/series.py:4433[0m, in [0;36mSeries.apply[0;34m(self, func, convert_dtype, args, **kwargs)[0m
[1;32m   4323[0m [38;5;28;01mdef[39;00m [38;5;21mapply[39m(
[1;32m   4324[0m     [38;5;28mself[39m,
[1;32m   4325[0m     func: AggFuncType,
[0;32m   (...)[0m
[1;32m   4328[0m     [38;5;241m*[39m[38;5;241m*[39mkwargs,
[1;32m   4329[0m ) [38;5;241m-[39m[38;5;241m>[39m DataFrame [38;5;241m|[39m Series:
[1;32m   4330[0m     [38;5;124;03m"""[39;00m
[1;32m   4331[0m [38;5;124;03m    Invoke function on values of Series.[39;00m
[1;32m   4332[0m 
[0;32m   (...)[0m
[1;32m   4431[0m [38;5;124;03m    dtype: float64[39;00m
[1;32m   4432[0m [38;5;124;03m    """[39;00m
[0;32m-> 4433[0m     [38;5;28;01mreturn[39;00m [43mSeriesApply[49m[43m([49m[38;5;28;43mself[39;49m[43m,[49m[43m [49m[43mfunc[49m[43m,[49m[43m [49m[43mconvert_dtype[49m[43m,[49m[43m [49m[43margs[49m[43m,[49m[43m [49m[43mkwargs[49m[43m)[49m[38;5;241;43m.[39;49m[43mapply[49m[43m([49m[43m)[49m

File [0;32m~/Environments/nlp/lib/python3.9/site-packages/pandas/core/apply.py:1082[0m, in [0;36mSeriesApply.apply[0;34m(self)[0m
[1;32m   1078[0m [38;5;28;01mif[39;00m [38;5;28misinstance[39m([38;5;28mself[39m[38;5;241m.[39mf, [38;5;28mstr[39m):
[1;32m   1079[0m     [38;5;66;03m# if we are a string, try to dispatch[39;00m
[1;32m   1080[0m     [38;5;28;01mreturn[39;00m [38;5;28mself[39m[38;5;241m.[39mapply_str()
[0;32m-> 1082[0m [38;5;28;01mreturn[39;00m [38;5;28;43mself[39;49m[38;5;241;43m.[39;49m[43mapply_standard[49m[43m([49m[43m)[49m

File [0;32m~/Environments/nlp/lib/python3.9/site-packages/pandas/core/apply.py:1137[0m, in [0;36mSeriesApply.apply_standard[0;34m(self)[0m
[1;32m   1131[0m         values [38;5;241m=[39m obj[38;5;241m.[39mastype([38;5;28mobject[39m)[38;5;241m.[39m_values
[1;32m   1132[0m         [38;5;66;03m# error: Argument 2 to "map_infer" has incompatible type[39;00m
[1;32m   1133[0m         [38;5;66;03m# "Union[Callable[..., Any], str, List[Union[Callable[..., Any], str]],[39;00m
[1;32m   1134[0m         [38;5;66;03m# Dict[Hashable, Union[Union[Callable[..., Any], str],[39;00m
[1;32m   1135[0m         [38;5;66;03m# List[Union[Callable[..., Any], str]]]]]"; expected[39;00m
[1;32m   1136[0m         [38;5;66;03m# "Callable[[Any], Any]"[39;00m
[0;32m-> 1137[0m         mapped [38;5;241m=[39m [43mlib[49m[38;5;241;43m.[39;49m[43mmap_infer[49m[43m([49m
[1;32m   1138[0m [43m            [49m[43mvalues[49m[43m,[49m
[1;32m   1139[0m [43m            [49m[43mf[49m[43m,[49m[43m  [49m[38;5;66;43;03m# type: ignore[arg-type][39;49;00m
[1;32m   1140[0m [43m            [49m[43mconvert[49m[38;5;241;43m=[39;49m[38;5;28;43mself[39;49m[38;5;241;43m.[39;49m[43mconvert_dtype[49m[43m,[49m
[1;32m   1141[0m [43m        [49m[43m)[49m
[1;32m   1143[0m [38;5;28;01mif[39;00m [38;5;28mlen[39m(mapped) [38;5;129;01mand[39;00m [38;5;28misinstance[39m(mapped[[38;5;241m0[39m], ABCSeries):
[1;32m   1144[0m     [38;5;66;03m# GH#43986 Need to do list(mapped) in order to get treated as nested[39;00m
[1;32m   1145[0m     [38;5;66;03m#  See also GH#25959 regarding EA support[39;00m
[1;32m   1146[0m     [38;5;28;01mreturn[39;00m obj[38;5;241m.[39m_constructor_expanddim([38;5;28mlist[39m(mapped), index[38;5;241m=[39mobj[38;5;241m.[39mindex)

File [0;32mpandas/_libs/lib.pyx:2870[0m, in [0;36mpandas._libs.lib.map_infer[0;34m()[0m

Input [0;32mIn [39][0m, in [0;36mconvert_tag[0;34m(tag)[0m
[1;32m      3[0m [38;5;28;01mdef[39;00m [38;5;21mconvert_tag[39m(tag):
[1;32m      4[0m     [38;5;28;01mif[39;00m tag[38;5;241m.[39mstartswith([38;5;124m'[39m[38;5;124mJ[39m[38;5;124m'[39m):
[0;32m----> 5[0m         tag [38;5;241m=[39m [43mwordnet[49m[38;5;241;43m.[39;49m[43mADJ[49m
[1;32m      6[0m     [38;5;28;01melif[39;00m tag[38;5;241m.[39mstartswith([38;5;124m'[39m[38;5;124mV[39m[38;5;124m'[39m):
[1;32m      7[0m         tag [38;5;241m=[39m wordnet[38;5;241m.[39mVERB

File [0;32m~/Environments/nlp/lib/python3.9/site-packages/nltk/corpus/util.py:121[0m, in [0;36mLazyCorpusLoader.__getattr__[0;34m(self, attr)[0m
[1;32m    118[0m [38;5;28;01mif[39;00m attr [38;5;241m==[39m [38;5;124m"[39m[38;5;124m__bases__[39m[38;5;124m"[39m:
[1;32m    119[0m     [38;5;28;01mraise[39;00m [38;5;167;01mAttributeError[39;00m([38;5;124m"[39m[38;5;124mLazyCorpusLoader object has no attribute [39m[38;5;124m'[39m[38;5;124m__bases__[39m[38;5;124m'[39m[38;5;124m"[39m)
[0;32m--> 121[0m [38;5;28;43mself[39;49m[38;5;241;43m.[39;49m[43m__load[49m[43m([49m[43m)[49m
[1;32m    122[0m [38;5;66;03m# This looks circular, but its not, since __load() changes our[39;00m
[1;32m    123[0m [38;5;66;03m# __class__ to something new:[39;00m
[1;32m    124[0m [38;5;28;01mreturn[39;00m [38;5;28mgetattr[39m([38;5;28mself[39m, attr)

File [0;32m~/Environments/nlp/lib/python3.9/site-packages/nltk/corpus/util.py:89[0m, in [0;36mLazyCorpusLoader.__load[0;34m(self)[0m
[1;32m     86[0m             [38;5;28;01mraise[39;00m e
[1;32m     88[0m [38;5;66;03m# Load the corpus.[39;00m
[0;32m---> 89[0m corpus [38;5;241m=[39m [38;5;28;43mself[39;49m[38;5;241;43m.[39;49m[43m__reader_cls[49m[43m([49m[43mroot[49m[43m,[49m[43m [49m[38;5;241;43m*[39;49m[38;5;28;43mself[39;49m[38;5;241;43m.[39;49m[43m__args[49m[43m,[49m[43m [49m[38;5;241;43m*[39;49m[38;5;241;43m*[39;49m[38;5;28;43mself[39;49m[38;5;241;43m.[39;49m[43m__kwargs[49m[43m)[49m
[1;32m     91[0m [38;5;66;03m# This is where the magic happens!  Transform ourselves into[39;00m
[1;32m     92[0m [38;5;66;03m# the corpus by modifying our own __dict__ and __class__ to[39;00m
[1;32m     93[0m [38;5;66;03m# match that of the corpus.[39;00m
[1;32m     95[0m args, kwargs [38;5;241m=[39m [38;5;28mself[39m[38;5;241m.[39m__args, [38;5;28mself[39m[38;5;241m.[39m__kwargs

File [0;32m~/Environments/nlp/lib/python3.9/site-packages/nltk/corpus/reader/wordnet.py:1176[0m, in [0;36mWordNetCorpusReader.__init__[0;34m(self, root, omw_reader)[0m
[1;32m   1172[0m     warnings[38;5;241m.[39mwarn(
[1;32m   1173[0m         [38;5;124m"[39m[38;5;124mThe multilingual functions are not available with this Wordnet version[39m[38;5;124m"[39m
[1;32m   1174[0m     )
[1;32m   1175[0m [38;5;28;01melse[39;00m:
[0;32m-> 1176[0m     [38;5;28mself[39m[38;5;241m.[39mprovenances [38;5;241m=[39m [38;5;28;43mself[39;49m[38;5;241;43m.[39;49m[43momw_prov[49m[43m([49m[43m)[49m
[1;32m   1178[0m [38;5;66;03m# A cache to store the wordnet data of multiple languages[39;00m
[1;32m   1179[0m [38;5;28mself[39m[38;5;241m.[39m_lang_data [38;5;241m=[39m defaultdict([38;5;28mlist[39m)

File [0;32m~/Environments/nlp/lib/python3.9/site-packages/nltk/corpus/reader/wordnet.py:1285[0m, in [0;36mWordNetCorpusReader.omw_prov[0;34m(self)[0m
[1;32m   1283[0m provdict [38;5;241m=[39m {}
[1;32m   1284[0m provdict[[38;5;124m"[39m[38;5;124meng[39m[38;5;124m"[39m] [38;5;241m=[39m [38;5;124m"[39m[38;5;124m"[39m
[0;32m-> 1285[0m fileids [38;5;241m=[39m [38;5;28;43mself[39;49m[38;5;241;43m.[39;49m[43m_omw_reader[49m[38;5;241;43m.[39;49m[43mfileids[49m()
[1;32m   1286[0m [38;5;28;01mfor[39;00m fileid [38;5;129;01min[39;00m fileids:
[1;32m   1287[0m     prov, langfile [38;5;241m=[39m os[38;5;241m.[39mpath[38;5;241m.[39msplit(fileid)

File [0;32m~/Environments/nlp/lib/python3.9/site-packages/nltk/corpus/util.py:121[0m, in [0;36mLazyCorpusLoader.__getattr__[0;34m(self, attr)[0m
[1;32m    118[0m [38;5;28;01mif[39;00m attr [38;5;241m==[39m [38;5;124m"[39m[38;5;124m__bases__[39m[38;5;124m"[39m:
[1;32m    119[0m     [38;5;28;01mraise[39;00m [38;5;167;01mAttributeError[39;00m([38;5;124m"[39m[38;5;124mLazyCorpusLoader object has no attribute [39m[38;5;124m'[39m[38;5;124m__bases__[39m[38;5;124m'[39m[38;5;124m"[39m)
[0;32m--> 121[0m [38;5;28;43mself[39;49m[38;5;241;43m.[39;49m[43m__load[49m[43m([49m[43m)[49m
[1;32m    122[0m [38;5;66;03m# This looks circular, but its not, since __load() changes our[39;00m
[1;32m    123[0m [38;5;66;03m# __class__ to something new:[39;00m
[1;32m    124[0m [38;5;28;01mreturn[39;00m [38;5;28mgetattr[39m([38;5;28mself[39m, attr)

File [0;32m~/Environments/nlp/lib/python3.9/site-packages/nltk/corpus/util.py:86[0m, in [0;36mLazyCorpusLoader.__load[0;34m(self)[0m
[1;32m     84[0m             root [38;5;241m=[39m nltk[38;5;241m.[39mdata[38;5;241m.[39mfind([38;5;124mf[39m[38;5;124m"[39m[38;5;132;01m{[39;00m[38;5;28mself[39m[38;5;241m.[39msubdir[38;5;132;01m}[39;00m[38;5;124m/[39m[38;5;132;01m{[39;00mzip_name[38;5;132;01m}[39;00m[38;5;124m"[39m)
[1;32m     85[0m         [38;5;28;01mexcept[39;00m [38;5;167;01mLookupError[39;00m:
[0;32m---> 86[0m             [38;5;28;01mraise[39;00m e
[1;32m     88[0m [38;5;66;03m# Load the corpus.[39;00m
[1;32m     89[0m corpus [38;5;241m=[39m [38;5;28mself[39m[38;5;241m.[39m__reader_cls(root, [38;5;241m*[39m[38;5;28mself[39m[38;5;241m.[39m__args, [38;5;241m*[39m[38;5;241m*[39m[38;5;28mself[39m[38;5;241m.[39m__kwargs)

File [0;32m~/Environments/nlp/lib/python3.9/site-packages/nltk/corpus/util.py:81[0m, in [0;36mLazyCorpusLoader.__load[0;34m(self)[0m
[1;32m     79[0m [38;5;28;01melse[39;00m:
[1;32m     80[0m     [38;5;28;01mtry[39;00m:
[0;32m---> 81[0m         root [38;5;241m=[39m [43mnltk[49m[38;5;241;43m.[39;49m[43mdata[49m[38;5;241;43m.[39;49m[43mfind[49m[43m([49m[38;5;124;43mf[39;49m[38;5;124;43m"[39;49m[38;5;132;43;01m{[39;49;00m[38;5;28;43mself[39;49m[38;5;241;43m.[39;49m[43msubdir[49m[38;5;132;43;01m}[39;49;00m[38;5;124;43m/[39;49m[38;5;132;43;01m{[39;49;00m[38;5;28;43mself[39;49m[38;5;241;43m.[39;49m[43m__name[49m[38;5;132;43;01m}[39;49;00m[38;5;124;43m"[39;49m[43m)[49m
[1;32m     82[0m     [38;5;28;01mexcept[39;00m [38;5;167;01mLookupError[39;00m [38;5;28;01mas[39;00m e:
[1;32m     83[0m         [38;5;28;01mtry[39;00m:

File [0;32m~/Environments/nlp/lib/python3.9/site-packages/nltk/data.py:583[0m, in [0;36mfind[0;34m(resource_name, paths)[0m
[1;32m    581[0m sep [38;5;241m=[39m [38;5;124m"[39m[38;5;124m*[39m[38;5;124m"[39m [38;5;241m*[39m [38;5;241m70[39m
[1;32m    582[0m resource_not_found [38;5;241m=[39m [38;5;124mf[39m[38;5;124m"[39m[38;5;130;01m\n[39;00m[38;5;132;01m{[39;00msep[38;5;132;01m}[39;00m[38;5;130;01m\n[39;00m[38;5;132;01m{[39;00mmsg[38;5;132;01m}[39;00m[38;5;130;01m\n[39;00m[38;5;132;01m{[39;00msep[38;5;132;01m}[39;00m[38;5;130;01m\n[39;00m[38;5;124m"[39m
[0;32m--> 583[0m [38;5;28;01mraise[39;00m [38;5;167;01mLookupError[39;00m(resource_not_found)

[0;31mLookupError[0m: 
**********************************************************************
  Resource [93momw-1.4[0m not found.
  Please use the NLTK Downloader to obtain the resource:

  [31m>>> import nltk
  >>> nltk.download('omw-1.4')
  [0m
  For more information see: https://www.nltk.org/data.html

  Attempted to load [93mcorpora/omw-1.4[0m

  Searched in:
    - '/Users/tyler/nltk_data'
    - '/Users/tyler/Environments/nlp/nltk_data'
    - '/Users/tyler/Environments/nlp/share/nltk_data'
    - '/Users/tyler/Environments/nlp/lib/nltk_data'
    - '/usr/share/nltk_data'
    - '/usr/local/share/nltk_data'
    - '/usr/lib/nltk_data'
    - '/usr/local/lib/nltk_data'
**********************************************************************

LookupError: 
**********************************************************************
  Resource [93momw-1.4[0m not found.
  Please use the NLTK Downloader to obtain the resource:

  [31m>>> import nltk
  >>> nltk.download('omw-1.4')
  [0m
  For more information see: https://www.nltk.org/data.html

  Attempted to load [93mcorpora/omw-1.4[0m

  Searched in:
    - '/Users/tyler/nltk_data'
    - '/Users/tyler/Environments/nlp/nltk_data'
    - '/Users/tyler/Environments/nlp/share/nltk_data'
    - '/Users/tyler/Environments/nlp/lib/nltk_data'
    - '/usr/share/nltk_data'
    - '/usr/local/share/nltk_data'
    - '/usr/lib/nltk_data'
    - '/usr/local/lib/nltk_data'
**********************************************************************


